2021-03-11 12:08:51,129 - [handler_log.py-->line:40] - INFO: ahsfkdhshf
2021-03-11 12:08:52,097 - [test_02login.py-->line:33] - ERROR: 用例--【登录成功】---执行失败
2021-03-11 12:08:52,098 - [test_02login.py-->line:34] - ERROR: 0 != 1001
Traceback (most recent call last):
  File "D:\pycharm\py35_project_api_v3\testcases\test_02login.py", line 30, in test_login
    self.assertEqual(expected['code'],res['code'])
  File "C:\Users\withzhangjihang\AppData\Local\Programs\Python\Python39\lib\unittest\case.py", line 831, in assertEqual
    assertion_func(first, second, msg=msg)
  File "C:\Users\withzhangjihang\AppData\Local\Programs\Python\Python39\lib\unittest\case.py", line 824, in _baseAssertEqual
    raise self.failureException(msg)
AssertionError: 0 != 1001
2021-03-11 12:08:52,250 - [test_02login.py-->line:37] - INFO: 用例--【手机号为空】---执行成功
2021-03-11 12:08:52,339 - [test_02login.py-->line:37] - INFO: 用例--【密码为空】---执行成功
2021-03-11 12:08:52,508 - [test_02login.py-->line:37] - INFO: 用例--【手机号未注册】---执行成功
2021-03-11 12:08:52,814 - [test_02login.py-->line:37] - INFO: 用例--【密码错误】---执行成功
2021-03-11 12:08:53,018 - [test_02login.py-->line:37] - INFO: 用例--【手机号格式错误】---执行成功
